Traceback (most recent call last):
  File "/usr/local/lib/python3.5/dist-packages/socks.py", line 747, in connect
    negotiate(self, dest_addr, dest_port)
  File "/usr/local/lib/python3.5/dist-packages/socks.py", line 419, in _negotiate_SOCKS5
    CONNECT, dest_addr)
  File "/usr/local/lib/python3.5/dist-packages/socks.py", line 494, in _SOCKS5_request
    raise SOCKS5Error("{0:#04x}: {1}".format(status, error))
socks.SOCKS5Error: 0x05: Connection refused

During handling of the above exception, another exception occurred:

Traceback (most recent call last):
  File "/usr/local/lib/python3.5/dist-packages/requests/packages/urllib3/contrib/socks.py", line 81, in _new_conn
    **extra_kw
  File "/usr/local/lib/python3.5/dist-packages/socks.py", line 205, in create_connection
    raise err
  File "/usr/local/lib/python3.5/dist-packages/socks.py", line 195, in create_connection
    sock.connect((remote_host, remote_port))
  File "/usr/local/lib/python3.5/dist-packages/socks.py", line 751, in connect
    raise GeneralProxyError("Socket error", error)
socks.GeneralProxyError: Socket error: 0x05: Connection refused

During handling of the above exception, another exception occurred:

Traceback (most recent call last):
  File "/usr/local/lib/python3.5/dist-packages/requests/packages/urllib3/connectionpool.py", line 595, in urlopen
    chunked=chunked)
  File "/usr/local/lib/python3.5/dist-packages/requests/packages/urllib3/connectionpool.py", line 352, in _make_request
    self._validate_conn(conn)
  File "/usr/local/lib/python3.5/dist-packages/requests/packages/urllib3/connectionpool.py", line 831, in _validate_conn
    conn.connect()
  File "/usr/local/lib/python3.5/dist-packages/requests/packages/urllib3/connection.py", line 254, in connect
    conn = self._new_conn()
  File "/usr/local/lib/python3.5/dist-packages/requests/packages/urllib3/contrib/socks.py", line 103, in _new_conn
    "Failed to establish a new connection: %s" % error
requests.packages.urllib3.exceptions.NewConnectionError: <requests.packages.urllib3.contrib.socks.SOCKSHTTPSConnection object at 0x7f0987bc4240>: Failed to establish a new connection: 0x05: Connection refused

During handling of the above exception, another exception occurred:

Traceback (most recent call last):
  File "/usr/local/lib/python3.5/dist-packages/requests/adapters.py", line 423, in send
    timeout=timeout
  File "/usr/local/lib/python3.5/dist-packages/requests/packages/urllib3/connectionpool.py", line 640, in urlopen
    _stacktrace=sys.exc_info()[2])
  File "/usr/local/lib/python3.5/dist-packages/requests/packages/urllib3/util/retry.py", line 287, in increment
    raise MaxRetryError(_pool, url, error or ResponseError(cause))
requests.packages.urllib3.exceptions.MaxRetryError: SOCKSHTTPSConnectionPool(host='ev7fnjzjdbtu3miq.onion', port=443): Max retries exceeded with url: /overchan.technology-0.json (Caused by NewConnectionError('<requests.packages.urllib3.contrib.socks.SOCKSHTTPSConnection object at 0x7f0987bc4240>: Failed to establish a new connection: 0x05: Connection refused',))

During handling of the above exception, another exception occurred:

Traceback (most recent call last):
  File "./yukko.py", line 759, in <module>
    boardView(settings["default board"])
  File "./yukko.py", line 196, in boardView
    currBoard = nntp.board(board, page)
  File "/home/faissaloo/Desktop/yukko/nntp.py", line 172, in __init__
    r = requests.get(node + boardname + "-" + str(page) + ".json", proxies=proxy)
  File "/usr/local/lib/python3.5/dist-packages/requests/api.py", line 70, in get
    return request('get', url, params=params, **kwargs)
  File "/usr/local/lib/python3.5/dist-packages/requests/api.py", line 56, in request
    return session.request(method=method, url=url, **kwargs)
  File "/usr/local/lib/python3.5/dist-packages/requests/sessions.py", line 475, in request
    resp = self.send(prep, **send_kwargs)
  File "/usr/local/lib/python3.5/dist-packages/requests/sessions.py", line 596, in send
    r = adapter.send(request, **kwargs)
  File "/usr/local/lib/python3.5/dist-packages/requests/adapters.py", line 487, in send
    raise ConnectionError(e, request=request)
requests.exceptions.ConnectionError: SOCKSHTTPSConnectionPool(host='ev7fnjzjdbtu3miq.onion', port=443): Max retries exceeded with url: /overchan.technology-0.json (Caused by NewConnectionError('<requests.packages.urllib3.contrib.socks.SOCKSHTTPSConnection object at 0x7f0987bc4240>: Failed to establish a new connection: 0x05: Connection refused',))
